Workbook

Sheet START HERE
A1: WORKLOAD & PROFIT PLAN - START HERE
A2: Click any sheet name to jump straight to it. Blue-text cells anywhere in this workbook are inputs you can change; green text is pulled from another sheet; black is calculated.
A4: 1 - WHERE YOU ENTER DATA | B4: What you put there | C4: How often
A5: TS Ahmed | B5: Paste Ahmed's monthly timesheet export into cell A4 | C5: Monthly
A6: TS Osama | B6: Paste Osama's monthly timesheet export into cell A4 | C6: Monthly
A7: TS Kirolos | B7: Paste Kirolos's monthly timesheet export into cell A4 | C7: Monthly
A8: Deliverables | B8: Progress: step reached, credit %, status date, engineer % split | C8: Monthly
A9: Deliverable Actuals | B9: Real milestone dates - submitted, comments received, resubmitted, completed (blue block W:AB) | C9: Monthly
A10: Support Plan | B10: Bengaluru and draftsman support: planned, delivered, office shift date and reason | C10: When resourcing changes
A11: Profit Plan | B11: Expected hours to finish each deliverable (column K) and the planning assumptions at the top | C11: When re-planning
A12: Phasing | B12: Planned MM overrides only (the block from row 93). Actual MM is now calculated from the timesheet - do not type in it. | C12: Rarely
A13: Inputs | B13: Project master data: budget MM, start and end dates, team availability | C13: When a project is added
A14: Work Calendar | B14: Working week, public holidays, engineer name patterns, hours per day | C14: Rarely
A16: 2 - WHERE YOU READ THE OUTPUT | B16: What it answers
A17: Delivery Sequence | B17: In what order should we deliver, and where does the year-end profit land?
A18: Profit Plan | B18: What does the rest of the year look like, and is the plan credible?
A19: Dashboard | B19: Portfolio KPIs for any year or quarter: planned, actual, earned, CPI, utilisation
A20: Mgmt Review | B20: Team performance, plan adherence, and dependency on draftsmen and Bengaluru
A21: Timesheet Daily | B21: Who charged what on every date: project, proposal, absence, overtime, idle or leave
A22: Deliverable Actuals | B22: Real start and finish dates, dormant days, stoppages, activity spells
A23: Proposals | B23: Proposal effort by real proposal number and by year
A24: Engineer KPIs | B24: Per-engineer performance measures
A25: Scorecard | B25: Summary scoring view
A26: Team Member | B26: Individual workload detail
A27: Analysis | B27: Quarterly efficiency and profitability by project
A28: Timesheet Raw | B28: Consolidated timesheet - read only, builds itself from the three TS sheets
A30: 3 - HOW THE WORKBOOK FLOWS
A31: The three TS sheets feed Timesheet Raw, which feeds Timesheet Daily (day-by-day) and Deliverable Actuals (deliverable-by-deliverable).
A32: Deliverable Actuals plus the Deliverables register feed the Profit Plan, which ranks the remaining work and produces the Delivery Sequence.
A33: Support Plan feeds the dependency section of Mgmt Review. Proposals feeds the proposal rows of the register.
A34: Inputs and Phasing feed Analysis, which feeds the Dashboard. Phasing actual MM is now calculated from the timesheet, so the Dashboard and Analysis move as soon as you paste.
A36: 4 - MONTHLY ROUTINE
A37: Step 1. Paste each engineer's export into TS Ahmed, TS Osama and TS Kirolos (cell A4, after deleting the old rows).
A38: Step 2. Open Work Calendar and check the DATA CHECK block: row count, date range, and that no rows are unmatched.
A39: Step 3. Update progress on the Deliverables register and milestone dates on Deliverable Actuals.
A40: Step 4. Nothing to retype for actual MM - Phasing now reads it from the timesheet. Just check the Dashboard and Analysis have moved.
A41: Step 5. Read the result on Delivery Sequence, Profit Plan and Mgmt Review.
A43: 5 - TAB COLOUR GUIDE
A44: Tabs are ordered and coloured by role, left to right.
A45: Purple | B45: Guide and glossary | C45: START HERE, Definitions
...

Sheet Definitions
A1: FIELD DEFINITIONS — HOW TO READ THE DASHBOARD
A2: ="All effort in Man-Months (MM). The Current column below is live and follows the Dashboard filter, showing: "&Dashboard!$H$5 -> All effort in Man-Months (MM). The Current column below is live and follows the Dashboard filter, showing: Full year 2026
A4: SECTION 1 — THE THREE CORE MEASURES (everything else is built from these)
A5: Field | B5: Where it appears | C5: What it actually means | D5: How it is calculated | E5: Current | F5: How to read it
A6: Planned MM | B6: Selected Period band | C6: The effort we SAID we would spend in this period. It comes from each project's budget spread across the months between its start and end date, so a 12 MM project running 2 years contributes 1.5 MM to each quarter. | D6: Straight-line spread of Budget across the project's start-to-end window, summed for every project touching the period. Overridable per project per quarter on the Phasing sheet. | E6: =Dashboard!$B$10 -> 44.829171 | F6: This is the yardstick, not an achievement. It answers: how much work was this period supposed to absorb?
A7: Actual MM | B7: Selected Period band | C7: The effort we REALLY spent in this period — the man-months your team actually booked against projects in those three months (or that year). | D7: Sum of the quarterly actuals grid on Phasing, for the quarters inside the selected period, across all projects and all three engineers. | E7: =Dashboard!$C$10 -> 17.908108 | F7: The only hard fact of the three. If this is blank, nobody logged time — the period is unmeasurable, not efficient.
A8: Earned MM | B8: Selected Period band | C8: The VALUE we delivered in this period, expressed in man-months of budget. If a project is 70% complete on a 26 MM budget, 18.2 MM of value has been earned regardless of how long it took. | D8: Budget x % Complete for each project, then spread across quarters in proportion to when the time was actually booked. | E8: =Dashboard!$D$10 -> 14.186137 | F8: This is what the client is effectively paying for. Compare it with Actual MM to see whether effort is converting into progress.
A10: SECTION 2 — PERIOD METRICS (flow: what happened inside the chosen window)
A11: Field | B11: Where it appears | C11: What it actually means | D11: How it is calculated | E11: Current | F11: How to read it
A12: Profit / (Loss) in period | B12: Selected Period band | C12: Value delivered less effort burned, in this period only. Positive means you got more budget-value out than man-months you put in. | D12: Earned MM less Actual MM. | E12: =Dashboard!$E$10 -> -3.7219708 | F12: A performance score for the period, NOT money in the bank. It says nothing about whether the project will finish in profit.
A13: Capacity MM | B13: Selected Period band | C13: How much the team could deliver in this period if fully applied to projects. | D13: Each person's availability % for that year x 3 months per quarter (x4 for a full year), summed across the team. | E13: =Dashboard!$F$10 -> 24.163043 | F13: The ceiling. Actual MM above this means overtime or the data is wrong; far below means the team was on other work.
A14: Utilisation | B14: Selected Period band | C14: How busy the team was: how much of the available capacity was actually booked to projects. | D14: Actual MM divided by Capacity MM. | E14: =Dashboard!$G$10 -> 0.74113628 | F14: Low utilisation usually means unlogged time or non-project work, not idleness. Check before drawing conclusions.
A15: Plan Adherence | B15: Selected Period band | C15: Did we burn the effort we said we would this period? | D15: Actual MM divided by Planned MM. | E15: =Dashboard!$H$10 -> 0.54727687 | F15: Below 100% means the plan assumed more effort than was spent — either you are behind, or the phasing dates need correcting.
A16: Efficiency (CPI) — in period | B16: Selected Period band | C16: Value delivered per man-month spent, IN THIS PERIOD ONLY. Above 1.00 means the period converted effort into progress well. | D16: Earned MM in period divided by Actual MM in period. | E16: =Dashboard!$I$10 -> 0.79216281 | F16: A snapshot of recent performance. Volatile — one quarter with little logged time can swing it wildly.
A19: SECTION 3 — READING EFFICIENCY CORRECTLY
A20: There is now one efficiency figure on the dashboard: Earned MM divided by Actual MM, for the period you selected. It answers a single question — did the effort spent in this window convert into delivered value? Above 1.00 is good. The traps below are the reason it sometimes looks wrong.
A21: What you see | C21: Why it happens | E21: What to do about it
A22: Reads n/a, or a dash | C22: No time was booked to any project in the period, so there is nothing to divide. | E22: Treat the period as unmeasured, not efficient. Check the actuals grid on Phasing for those quarters.
A23: Far above 1.00 (say over 2.00x) | C23: A project is marked well advanced on very little booked time, so earned value dwarfs actual effort. | E23: Almost always missing actuals or an overstated budget. Compare Actual to Date against Budget in Project Detail.
A24: Below 1.00 | C24: More effort has been spent than value delivered. This is a genuine overrun. | E24: Real signal. Look at Cost at Completion versus Budget per project in Project Detail to find which contract is causing it.
A25: Swings hard between quarters | C25: Period figures are volatile by nature — one quarter of light logging moves them a long way. | E25: Switch the filter to Year, or scan several quarters, before concluding anything about a trend.
A27: ="For the period currently selected ("&Dashboard!$H$5&") efficiency reads "&IF(Dashboard!$C$10=0,"n/a — no time booked",TEXT(Dashboard!$I$10,"0.00")&"x, from "&TEXT(Dashboard!$D$10,"0.00")&" MM of value delivered against "&TEXT(Dashboard!$C$10,"0.00")&" MM of effort booked.") -> For the period currently selected (Full year 2026) efficiency reads 0.79x, from 14.19 MM of value delivered against 17.91 MM of effort booked.
A31: SECTION 4 — BEFORE YOU TRUST ANY OF THESE NUMBERS
A32: 1. Efficiency is only as good as the logged time. A project marked 100% complete with almost no booked MM will show an impossibly high CPI and flatter the portfolio. Check Actual to Date against Budget on the Inputs sheet before believing a number above about 2.00x.
A33: 2. Planned MM depends entirely on the Start and End dates. If a date is wrong, that project's effort lands in the wrong quarters and Plan Adherence becomes meaningless.
A34: 3. % Complete drives Earned MM and Forecast at Completion. It is a judgement you type in — if it is stale, both the efficiency and the forecast loss are stale too.
A35: 4. Effort booked before quarterly tracking began sits in the Opening column on Phasing. It counts toward a project's total booked time but falls inside no quarter, so it never appears in any period figure.

Sheet Dashboard
A1: PROJECT PORTFOLIO DASHBOARD
A2: ="All effort in Man-Months (MM) | "&TEXT(Inputs!$M$86,"0")&" projects in scope of "&TEXT(COUNTA(Inputs!$A$6:$A$85),"0")&" | Team of "&TEXT(COUNTA(Inputs!$A$91:$A$93),"0")&" | Reported "&TEXT(TODAY(),"dd mmm yyyy") -> All effort in Man-Months (MM) | 9 projects in scope of 40 | Team of 3 | Reported 01 Sep 2026
A4: PERIOD FILTER — choose how you want to look at the portfolio
A5: View by: | B5: Year | C5: Year: | D5: 2026 | E5: Quarter: | F5: Q1 | G5: Showing: | H5: =IF($B$5="All Time","All periods, including opening balances",IF($B$5="Year","Full year "&TEXT($D$5,"0"),$F$5&" "&TEXT($D$5,"0")&" ("&TEXT($D$6,"dd mmm")&" to "&TEXT($F$6,"dd mmm yyyy")&")")) -> Full year 2026
A6: Resolved period → | B6: =$F$5&"-"&TEXT(MOD($D$5,100),"00") -> Q1-26 | C6: from | D6: =IF($B$5="All Time",DATE(1900,1,1),IF($B$5="Year",DATE($D$5,1,1),DATE($D$5,(VALUE(MID($F$5,2,1))-1)*3+1,1))) -> 46023 | E6: to | F6: =IF($B$5="All Time",DATE(2099,12,31),IF($B$5="Year",DATE($D$5,12,31),EOMONTH($D$6,2))) -> 46387 | G6: As at: | H6: =Inputs!$B$96 -> 46266 | I6: Elapsed: | J6: =IF(IF($B$5="All Time",Analysis!$Y$24,IF($B$5="Year",SUMIF(Analysis!$E$3:$X$3,$D$5,Analysis!$E$24:$X$24),SUMIF(Analysis!$E$4:$X$4,$B$6,Analysis!$E$24:$X$24)))=0,"",$F$10/(IF($B$5="All Time",Analysis!$Y$24,IF($B$5="Year",SUMIF(Analysis!$E$3:$X$3,$D$5,Analysis!$E$24:$X$24),SUMIF(Analysis!$E$4:$X$4,$B$6,Analysis!$E$24:$X$24))))) -> 0.67119565 | K6: Planned to date: | L6: =IF($B$5="All Time",Analysis!$Y$33,IF($B$5="Year",SUMIF(Analysis!$E$3:$X$3,$D$5,Analysis!$E$33:$X$33),SUMIF(Analysis!$E$4:$X$4,$B$6,Analysis!$E$33:$X$33))) -> 32.722209
A8: SELECTED PERIOD — PERFORMANCE IN THE PERIOD YOU CHOSE ABOVE
B9: Planned MM (full period) | C9: Actual MM | D9: Earned MM | E9: Profit / (Loss) | F9: Capacity to Date | G9: Utilisation | H9: Plan Adherence to Date | I9: Efficiency (CPI) | J9: Projects Active
B10: =IF($B$5="All Time",Analysis!$Y$17,IF($B$5="Year",SUMIF(Analysis!$E$3:$X$3,$D$5,Analysis!$E$17:$X$17),SUMIF(Analysis!$E$4:$X$4,$B$6,Analysis!$E$17:$X$17))) -> 44.829171 | C10: =IF($B$5="All Time",Analysis!$Y$18,IF($B$5="Year",SUMIF(Analysis!$E$3:$X$3,$D$5,Analysis!$E$18:$X$18),SUMIF(Analysis!$E$4:$X$4,$B$6,Analysis!$E$18:$X$18))) -> 17.908108 | D10: =IF($B$5="All Time",Analysis!$Y$19,IF($B$5="Year",SUMIF(Analysis!$E$3:$X$3,$D$5,Analysis!$E$19:$X$19),SUMIF(Analysis!$E$4:$X$4,$B$6,Analysis!$E$19:$X$19))) -> 14.186137 | E10: =D10-C10 -> -3.7219708 | F10: =IF($B$5="All Time",Analysis!$Y$32,IF($B$5="Year",SUMIF(Analysis!$E$3:$X$3,$D$5,Analysis!$E$32:$X$32),SUMIF(Analysis!$E$4:$X$4,$B$6,Analysis!$E$32:$X$32))) -> 24.163043 | G10: =IF(F10=0,"n/a",C10/F10) -> 0.74113628 | H10: =IF($L$6=0,"n/a",C10/$L$6) -> 0.54727687 | I10: =IF(C10=0,"n/a",D10/C10) -> 0.79216281 | J10: {=SUMPRODUCT((Inputs!$A$6:$A$85<>"")*(Inputs!$D$6:$D$85<=$F$6)*(Inputs!$E$6:$E$85>=$D$6))} -> 16
B11: ="full period plan" -> full period plan | C11: ="what we actually burned" -> what we actually burned | D11: ="value delivered" -> value delivered | E11: ="earned minus actual" -> earned minus actual | F11: ="pro-rated to "&TEXT($H$6,"dd mmm") -> pro-rated to 01 Sep | G11: ="actual vs capacity to date" -> actual vs capacity to date | H11: ="vs "&TEXT($L$6,"0.00")&" MM planned to date" -> vs 32.72 MM planned to date | I11: ="above 1.00 is good" -> above 1.00 is good | J11: ="live in this period" -> live in this period
A13: WHAT IS ACTUALLY BEING WORKED — PORTFOLIO BY STATUS
A14: Status | B14: Projects | C14: Budget | D14: Planned in Period | E14: Actual in Period | F14: Remaining on Hand | G14: Cost at Compl. | H14: Profit / (Loss) | I14: In Scope?
A15: Active | B15: {=SUMPRODUCT((Inputs!$F$6:$F$85=$A15)*$M$173:$M$252)} -> 6 | C15: {=SUMPRODUCT((Inputs!$F$6:$F$85=$A15)*$M$173:$M$252*$B$173:$B$252)} -> 35.55 | D15: {=SUMPRODUCT((Inputs!$F$6:$F$85=$A15)*$M$173:$M$252*$K$173:$K$252)} -> 28.315241 | E15: {=SUMPRODUCT((Inputs!$F$6:$F$85=$A15)*$M$173:$M$252*$L$173:$L$252)} -> 14.166216 | F15: {=SUMPRODUCT((Inputs!$F$6:$F$85=$A15)*$M$173:$M$252*$I$173:$I$252)} -> 48.568178 | G15: {=SUMPRODUCT((Inputs!$F$6:$F$85=$A15)*$M$173:$M$252*$H$173:$H$252)} -> 68.214124 | H15: {=SUMPRODUCT((Inputs!$F$6:$F$85=$A15)*$M$173:$M$252*$J$173:$J$252)} -> -32.664124 | I15: =IF(OR($A15="Active",$A15="Not Started"),"Yes","No") -> Yes
A16: Not Started | B16: {=SUMPRODUCT((Inputs!$F$6:$F$85=$A16)*$M$173:$M$252)} -> 1 | C16: {=SUMPRODUCT((Inputs!$F$6:$F$85=$A16)*$M$173:$M$252*$B$173:$B$252)} -> 5 | D16: {=SUMPRODUCT((Inputs!$F$6:$F$85=$A16)*$M$173:$M$252*$K$173:$K$252)} -> 1.2585499 | E16: {=SUMPRODUCT((Inputs!$F$6:$F$85=$A16)*$M$173:$M$252*$L$173:$L$252)} -> 0 | F16: {=SUMPRODUCT((Inputs!$F$6:$F$85=$A16)*$M$173:$M$252*$I$173:$I$252)} -> 5 | G16: {=SUMPRODUCT((Inputs!$F$6:$F$85=$A16)*$M$173:$M$252*$H$173:$H$252)} -> 5 | H16: {=SUMPRODUCT((Inputs!$F$6:$F$85=$A16)*$M$173:$M$252*$J$173:$J$252)} -> 0 | I16: =IF(OR($A16="Active",$A16="Not Started"),"Yes","No") -> Yes
A17: On Hold | B17: {=SUMPRODUCT((Inputs!$F$6:$F$85=$A17)*$M$173:$M$252)} -> 7 | C17: {=SUMPRODUCT((Inputs!$F$6:$F$85=$A17)*$M$173:$M$252*$B$173:$B$252)} -> 18.4 | D17: {=SUMPRODUCT((Inputs!$F$6:$F$85=$A17)*$M$173:$M$252*$K$173:$K$252)} -> 9.5972454 | E17: {=SUMPRODUCT((Inputs!$F$6:$F$85=$A17)*$M$173:$M$252*$L$173:$L$252)} -> 1.3540541 | F17: {=SUMPRODUCT((Inputs!$F$6:$F$85=$A17)*$M$173:$M$252*$I$173:$I$252)} -> 26.772302 | G17: {=SUMPRODUCT((Inputs!$F$6:$F$85=$A17)*$M$173:$M$252*$H$173:$H$252)} -> 35.793923 | H17: {=SUMPRODUCT((Inputs!$F$6:$F$85=$A17)*$M$173:$M$252*$J$173:$J$252)} -> -17.393923 | I17: =IF(OR($A17="Active",$A17="Not Started"),"Yes","No") -> No
A18: Finalized | B18: {=SUMPRODUCT((Inputs!$F$6:$F$85=$A18)*$M$173:$M$252)} -> 2 | C18: {=SUMPRODUCT((Inputs!$F$6:$F$85=$A18)*$M$173:$M$252*$B$173:$B$252)} -> 9 | D18: {=SUMPRODUCT((Inputs!$F$6:$F$85=$A18)*$M$173:$M$252*$K$173:$K$252)} -> 5.6581353 | E18: {=SUMPRODUCT((Inputs!$F$6:$F$85=$A18)*$M$173:$M$252*$L$173:$L$252)} -> 1.9472973 | F18: {=SUMPRODUCT((Inputs!$F$6:$F$85=$A18)*$M$173:$M$252*$I$173:$I$252)} -> 0 | G18: {=SUMPRODUCT((Inputs!$F$6:$F$85=$A18)*$M$173:$M$252*$H$173:$H$252)} -> 4.8905405 | H18: {=SUMPRODUCT((Inputs!$F$6:$F$85=$A18)*$M$173:$M$252*$J$173:$J$252)} -> 4.1094595 | I18: =IF(OR($A18="Active",$A18="Not Started"),"Yes","No") -> No
A19: Proposal | B19: {=SUMPRODUCT((Inputs!$F$6:$F$85=$A19)*$M$173:$M$252)} -> 0 | C19: {=SUMPRODUCT((Inputs!$F$6:$F$85=$A19)*$M$173:$M$252*$B$173:$B$252)} -> 0 | D19: {=SUMPRODUCT((Inputs!$F$6:$F$85=$A19)*$M$173:$M$252*$K$173:$K$252)} -> 0 | E19: {=SUMPRODUCT((Inputs!$F$6:$F$85=$A19)*$M$173:$M$252*$L$173:$L$252)} -> 0 | F19: {=SUMPRODUCT((Inputs!$F$6:$F$85=$A19)*$M$173:$M$252*$I$173:$I$252)} -> 0 | G19: {=SUMPRODUCT((Inputs!$F$6:$F$85=$A19)*$M$173:$M$252*$H$173:$H$252)} -> 0 | H19: {=SUMPRODUCT((Inputs!$F$6:$F$85=$A19)*$M$173:$M$252*$J$173:$J$252)} -> 0 | I19: =IF(OR($A19="Active",$A19="Not Started"),"Yes","No") -> No
A20: Cancelled | B20: {=SUMPRODUCT((Inputs!$F$6:$F$85=$A20)*$M$173:$M$252)} -> 0 | C20: {=SUMPRODUCT((Inputs!$F$6:$F$85=$A20)*$M$173:$M$252*$B$173:$B$252)} -> 0 | D20: {=SUMPRODUCT((Inputs!$F$6:$F$85=$A20)*$M$173:$M$252*$K$173:$K$252)} -> 0 | E20: {=SUMPRODUCT((Inputs!$F$6:$F$85=$A20)*$M$173:$M$252*$L$173:$L$252)} -> 0 | F20: {=SUMPRODUCT((Inputs!$F$6:$F$85=$A20)*$M$173:$M$252*$I$173:$I$252)} -> 0 | G20: {=SUMPRODUCT((Inputs!$F$6:$F$85=$A20)*$M$173:$M$252*$H$173:$H$252)} -> 0 | H20: {=SUMPRODUCT((Inputs!$F$6:$F$85=$A20)*$M$173:$M$252*$J$173:$J$252)} -> 0 | I20: =IF(OR($A20="Active",$A20="Not Started"),"Yes","No") -> No
A21: ALL LIVE IN PERIOD | B21: =SUM(B15:B20) -> 16 | C21: =SUM(C15:C20) -> 67.95 | D21: =SUM(D15:D20) -> 44.829171 | E21: =SUM(E15:E20) -> 17.467568 | F21: =SUM(F15:F20) -> 80.34048 | G21: =SUM(G15:G20) -> 113.89859 | H21: =SUM(H15:H20) -> -45.948588 | I21: =""
A22: IN DELIVERY SCOPE | B22: =SUM(B15:B16) -> 7 | C22: =SUM(C15:C16) -> 40.55 | D22: =SUM(D15:D16) -> 29.573791 | E22: =SUM(E15:E16) -> 14.166216 | F22: =SUM(F15:F16) -> 53.568178 | G22: =SUM(G15:G16) -> 73.214124 | H22: =SUM(H15:H16) -> -32.664124 | I22: =""
A24: PROJECT DETAIL — only projects live in the selected period
A25: Project | B25: Budget | C25: Start | D25: End | E25: Status | F25: % Compl. | G25: Actual to Date | H25: Cost at Compl. | I25: Remaining | J25: Profit / (Loss) | K25: Planned in Period | L25: Actual in Period | M25: % of Period Plan
A26: =IFERROR(INDEX($A$173:$A$252,MATCH(ROW()-25,$N$173:$N$252,0)),"") -> N25178-0100D | B26: =IF($A26="","",INDEX($B$173:$B$252,MATCH(ROW()-25,$N$173:$N$252,0))) -> 2.4 | C26: =IF($A26="","",INDEX($C$173:$C$252,MATCH(ROW()-25,$N$173:$N$252,0))) -> 46204 | D26: =IF($A26="","",INDEX($D$173:$D$252,MATCH(ROW()-25,$N$173:$N$252,0))) -> 46295 | E26: =IF($A26="","",INDEX($E$173:$E$252,MATCH(ROW()-25,$N$173:$N$252,0))) -> Active | F26: =IF($A26="","",INDEX($F$173:$F$252,MATCH(ROW()-25,$N$173:$N$252,0))) -> 0.65 | G26: =IF($A26="","",INDEX($G$173:$G$252,MATCH(ROW()-25,$N$173:$N$252,0))) -> 0 | H26: =IF($A26="","",INDEX($H$173:$H$252,MATCH(ROW()-25,$N$173:$N$252,0))) -> 2.4 | I26: =IF($A26="","",INDEX($I$173:$I$252,MATCH(ROW()-25,$N$173:$N$252,0))) -> 2.4 | J26: =IF($A26="","",INDEX($J$173:$J$252,MATCH(ROW()-25,$N$173:$N$252,0))) -> 0 | K26: =IF($A26="","",INDEX($K$173:$K$252,MATCH(ROW()-25,$N$173:$N$252,0))) -> 2.4 | L26: =IF($A26="","",INDEX($L$173:$L$252,MATCH(ROW()-25,$N$173:$N$252,0))) -> 0 | M26: =IF($A26="","",IF($K$106=0,"",$K26/$K$106)) -> 0.053536568
A27: =IFERROR(INDEX($A$173:$A$252,MATCH(ROW()-25,$N$173:$N$252,0)),"") -> E26084-0100D | B27: =IF($A27="","",INDEX($B$173:$B$252,MATCH(ROW()-25,$N$173:$N$252,0))) -> 3 | C27: =IF($A27="","",INDEX($C$173:$C$252,MATCH(ROW()-25,$N$173:$N$252,0))) -> 45839 | D27: =IF($A27="","",INDEX($D$173:$D$252,MATCH(ROW()-25,$N$173:$N$252,0))) -> 46295 | E27: =IF($A27="","",INDEX($E$173:$E$252,MATCH(ROW()-25,$N$173:$N$252,0))) -> Active | F27: =IF($A27="","",INDEX($F$173:$F$252,MATCH(ROW()-25,$N$173:$N$252,0))) -> 0.1625 | G27: =IF($A27="","",INDEX($G$173:$G$252,MATCH(ROW()-25,$N$173:$N$252,0))) -> 0.22567568 | H27: =IF($A27="","",INDEX($H$173:$H$252,MATCH(ROW()-25,$N$173:$N$252,0))) -> 1.3887734 | I27: =IF($A27="","",INDEX($I$173:$I$252,MATCH(ROW()-25,$N$173:$N$252,0))) -> 1.1630977 | J27: =IF($A27="","",INDEX($J$173:$J$252,MATCH(ROW()-25,$N$173:$N$252,0))) -> 1.6112266 | K27: =IF($A27="","",INDEX($K$173:$K$252,MATCH(ROW()-25,$N$173:$N$252,0))) -> 1.7921225 | L27: =IF($A27="","",INDEX($L$173:$L$252,MATCH(ROW()-25,$N$173:$N$252,0))) -> 0.22567568 | M27: =IF($A27="","",IF($K$106=0,"",$K27/$K$106)) -> 0.039976705
A28: =IFERROR(INDEX($A$173:$A$252,MATCH(ROW()-25,$N$173:$N$252,0)),"") -> N25185-0100D | B28: =IF($A28="","",INDEX($B$173:$B$252,MATCH(ROW()-25,$N$173:$N$252,0))) -> 26 | C28: =IF($A28="","",INDEX($C$173:$C$252,MATCH(ROW()-25,$N$173:$N$252,0))) -> 45931 | D28: =IF($A28="","",INDEX($D$173:$D$252,MATCH(ROW()-25,$N$173:$N$252,0))) -> 46387 | E28: =IF($A28="","",INDEX($E$173:$E$252,MATCH(ROW()-25,$N$173:$N$252,0))) -> Active | F28: =IF($A28="","",INDEX($F$173:$F$252,MATCH(ROW()-25,$N$173:$N$252,0))) -> 0.316 | G28: =IF($A28="","",INDEX($G$173:$G$252,MATCH(ROW()-25,$N$173:$N$252,0))) -> 18.516216 | H28: =IF($A28="","",INDEX($H$173:$H$252,MATCH(ROW()-25,$N$173:$N$252,0))) -> 58.595621 | I28: =IF($A28="","",INDEX($I$173:$I$252,MATCH(ROW()-25,$N$173:$N$252,0))) -> 40.079405 | J28: =IF($A28="","",INDEX($J$173:$J$252,MATCH(ROW()-25,$N$173:$N$252,0))) -> -32.595621 | K28: =IF($A28="","",INDEX($K$173:$K$252,MATCH(ROW()-25,$N$173:$N$252,0))) -> 20.765864 | L28: =IF($A28="","",INDEX($L$173:$L$252,MATCH(ROW()-25,$N$173:$N$252,0))) -> 13.517568 | M28: =IF($A28="","",IF($K$106=0,"",$K28/$K$106)) -> 0.46322213
A29: =IFERROR(INDEX($A$173:$A$252,MATCH(ROW()-25,$N$173:$N$252,0)),"") -> D26058-0100D | B29: =IF($A29="","",INDEX($B$173:$B$252,MATCH(ROW()-25,$N$173:$N$252,0))) -> 5 | C29: =IF($A29="","",INDEX($C$173:$C$252,MATCH(ROW()-25,$N$173:$N$252,0))) -> 46204 | D29: =IF($A29="","",INDEX($D$173:$D$252,MATCH(ROW()-25,$N$173:$N$252,0))) -> 46934 | E29: =IF($A29="","",INDEX($E$173:$E$252,MATCH(ROW()-25,$N$173:$N$252,0))) -> Not Started | F29: =IF($A29="","",INDEX($F$173:$F$252,MATCH(ROW()-25,$N$173:$N$252,0))) -> 0 | G29: =IF($A29="","",INDEX($G$173:$G$252,MATCH(ROW()-25,$N$173:$N$252,0))) -> 0 | H29: =IF($A29="","",INDEX($H$173:$H$252,MATCH(ROW()-25,$N$173:$N$252,0))) -> 5 | I29: =IF($A29="","",INDEX($I$173:$I$252,MATCH(ROW()-25,$N$173:$N$252,0))) -> 5 | J29: =IF($A29="","",INDEX($J$173:$J$252,MATCH(ROW()-25,$N$173:$N$252,0))) -> 0 | K29: =IF($A29="","",INDEX($K$173:$K$252,MATCH(ROW()-25,$N$173:$N$252,0))) -> 1.2585499 | L29: =IF($A29="","",INDEX($L$173:$L$252,MATCH(ROW()-25,$N$173:$N$252,0))) -> 0 | M29: =IF($A29="","",IF($K$106=0,"",$K29/$K$106)) -> 0.028074352
A30: =IFERROR(INDEX($A$173:$A$252,MATCH(ROW()-25,$N$173:$N$252,0)),"") -> AN23207-0500D | B30: =IF($A30="","",INDEX($B$173:$B$252,MATCH(ROW()-25,$N$173:$N$252,0))) -> 1.15 | C30: =IF($A30="","",INDEX($C$173:$C$252,MATCH(ROW()-25,$N$173:$N$252,0))) -> 46023 | D30: =IF($A30="","",INDEX($D$173:$D$252,MATCH(ROW()-25,$N$173:$N$252,0))) -> 46112 | E30: =IF($A30="","",INDEX($E$173:$E$252,MATCH(ROW()-25,$N$173:$N$252,0))) -> On Hold | F30: =IF($A30="","",INDEX($F$173:$F$252,MATCH(ROW()-25,$N$173:$N$252,0))) -> 0.65 | G30: =IF($A30="","",INDEX($G$173:$G$252,MATCH(ROW()-25,$N$173:$N$252,0))) -> 0 | H30: =IF($A30="","",INDEX($H$173:$H$252,MATCH(ROW()-25,$N$173:$N$252,0))) -> 1.15 | I30: =IF($A30="","",INDEX($I$173:$I$252,MATCH(ROW()-25,$N$173:$N$252,0))) -> 1.15 | J30: =IF($A30="","",INDEX($J$173:$J$252,MATCH(ROW()-25,$N$173:$N$252,0))) -> 0 | K30: =IF($A30="","",INDEX($K$173:$K$252,MATCH(ROW()-25,$N$173:$N$252,0))) -> 1.15 | L30: =IF($A30="","",INDEX($L$173:$L$252,MATCH(ROW()-25,$N$173:$N$252,0))) -> 0 | M30: =IF($A30="","",IF($K$106=0,"",$K30/$K$106)) -> 0.025652939
A31: =IFERROR(INDEX($A$173:$A$252,MATCH(ROW()-25,$N$173:$N$252,0)),"") -> AN23276-0100D | B31: =IF($A31="","",INDEX($B$173:$B$252,MATCH(ROW()-25,$N$173:$N$252,0))) -> 5 | C31: =IF($A31="","",INDEX($C$173:$C$252,MATCH(ROW()-25,$N$173:$N$252,0))) -> 45474 | D31: =IF($A31="","",INDEX($D$173:$D$252,MATCH(ROW()-25,$N$173:$N$252,0))) -> 46295 | E31: =IF($A31="","",INDEX($E$173:$E$252,MATCH(ROW()-25,$N$173:$N$252,0))) -> On Hold | F31: =IF($A31="","",INDEX($F$173:$F$252,MATCH(ROW()-25,$N$173:$N$252,0))) -> 0.9 | G31: =IF($A31="","",INDEX($G$173:$G$252,MATCH(ROW()-25,$N$173:$N$252,0))) -> 0.88918919 | H31: =IF($A31="","",INDEX($H$173:$H$252,MATCH(ROW()-25,$N$173:$N$252,0))) -> 0.98798799 | I31: =IF($A31="","",INDEX($I$173:$I$252,MATCH(ROW()-25,$N$173:$N$252,0))) -> 0.098798799 | J31: =IF($A31="","",INDEX($J$173:$J$252,MATCH(ROW()-25,$N$173:$N$252,0))) -> 4.012012 | K31: =IF($A31="","",INDEX($K$173:$K$252,MATCH(ROW()-25,$N$173:$N$252,0))) -> 1.6605839 | L31: =IF($A31="","",INDEX($L$173:$L$252,MATCH(ROW()-25,$N$173:$N$252,0))) -> 0 | M31: =IF($A31="","",IF($K$106=0,"",$K31/$K$106)) -> 0.037042486
A32: =IFERROR(INDEX($A$173:$A$252,MATCH(ROW()-25,$N$173:$N$252,0)),"") -> AN24073-0100D | B32: =IF($A32="","",INDEX($B$173:$B$252,MATCH(ROW()-25,$N$173:$N$252,0))) -> 1.25 | C32: =IF($A32="","",INDEX($C$173:$C$252,MATCH(ROW()-25,$N$173:$N$252,0))) -> 45839 | D32: =IF($A32="","",INDEX($D$173:$D$252,MATCH(ROW()-25,$N$173:$N$252,0))) -> 46295 | E32: =IF($A32="","",INDEX($E$173:$E$252,MATCH(ROW()-25,$N$173:$N$252,0))) -> On Hold | F32: =IF($A32="","",INDEX($F$173:$F$252,MATCH(ROW()-25,$N$173:$N$252,0))) -> 0.9 | G32: =IF($A32="","",INDEX($G$173:$G$252,MATCH(ROW()-25,$N$173:$N$252,0))) -> 0.92432432 | H32: =IF($A32="","",INDEX($H$173:$H$252,MATCH(ROW()-25,$N$173:$N$252,0))) -> 1.027027 | I32: =IF($A32="","",INDEX($I$173:$I$252,MATCH(ROW()-25,$N$173:$N$252,0))) -> 0.1027027 | J32: =IF($A32="","",INDEX($J$173:$J$252,MATCH(ROW()-25,$N$173:$N$252,0))) -> 0.22297297 | K32: =IF($A32="","",INDEX($K$173:$K$252,MATCH(ROW()-25,$N$173:$N$252,0))) -> 0.74671772 | L32: =IF($A32="","",INDEX($L$173:$L$252,MATCH(ROW()-25,$N$173:$N$252,0))) -> 0 | M32: =IF($A32="","",IF($K$106=0,"",$K32/$K$106)) -> 0.01665696
A33: =IFERROR(INDEX($A$173:$A$252,MATCH(ROW()-25,$N$173:$N$252,0)),"") -> AN24140-0100R | B33: =IF($A33="","",INDEX($B$173:$B$252,MATCH(ROW()-25,$N$173:$N$252,0))) -> 1.5 | C33: =IF($A33="","",INDEX($C$173:$C$252,MATCH(ROW()-25,$N$173:$N$252,0))) -> 45717 | D33: =IF($A33="","",INDEX($D$173:$D$252,MATCH(ROW()-25,$N$173:$N$252,0))) -> 46295 | E33: =IF($A33="","",INDEX($E$173:$E$252,MATCH(ROW()-25,$N$173:$N$252,0))) -> Active | F33: =IF($A33="","",INDEX($F$173:$F$252,MATCH(ROW()-25,$N$173:$N$252,0))) -> 0.1 | G33: =IF($A33="","",INDEX($G$173:$G$252,MATCH(ROW()-25,$N$173:$N$252,0))) -> 0.5027027 | H33: =IF($A33="","",INDEX($H$173:$H$252,MATCH(ROW()-25,$N$173:$N$252,0))) -> 5.027027 | I33: =IF($A33="","",INDEX($I$173:$I$252,MATCH(ROW()-25,$N$173:$N$252,0))) -> 4.5243243 | J33: =IF($A33="","",INDEX($J$173:$J$252,MATCH(ROW()-25,$N$173:$N$252,0))) -> -3.527027 | K33: =IF($A33="","",INDEX($K$173:$K$252,MATCH(ROW()-25,$N$173:$N$252,0))) -> 0.70725389 | L33: =IF($A33="","",INDEX($L$173:$L$252,MATCH(ROW()-25,$N$173:$N$252,0))) -> 0.021621622 | M33: =IF($A33="","",IF($K$106=0,"",$K33/$K$106)) -> 0.015776644
A34: =IFERROR(INDEX($A$173:$A$252,MATCH(ROW()-25,$N$173:$N$252,0)),"") -> CS24035-0100D | B34: =IF($A34="","",INDEX($B$173:$B$252,MATCH(ROW()-25,$N$173:$N$252,0))) -> 4 | C34: =IF($A34="","",INDEX($C$173:$C$252,MATCH(ROW()-25,$N$173:$N$252,0))) -> 45931 | D34: =IF($A34="","",INDEX($D$173:$D$252,MATCH(ROW()-25,$N$173:$N$252,0))) -> 46387 | E34: =IF($A34="","",INDEX($E$173:$E$252,MATCH(ROW()-25,$N$173:$N$252,0))) -> On Hold | F34: =IF($A34="","",INDEX($F$173:$F$252,MATCH(ROW()-25,$N$173:$N$252,0))) -> 0.85 | G34: =IF($A34="","",INDEX($G$173:$G$252,MATCH(ROW()-25,$N$173:$N$252,0))) -> 3.1324324 | H34: =IF($A34="","",INDEX($H$173:$H$252,MATCH(ROW()-25,$N$173:$N$252,0))) -> 3.6852146 | I34: =IF($A34="","",INDEX($I$173:$I$252,MATCH(ROW()-25,$N$173:$N$252,0))) -> 0.55278219 | J34: =IF($A34="","",INDEX($J$173:$J$252,MATCH(ROW()-25,$N$173:$N$252,0))) -> 0.31478537 | K34: =IF($A34="","",INDEX($K$173:$K$252,MATCH(ROW()-25,$N$173:$N$252,0))) -> 3.1947484 | L34: =IF($A34="","",INDEX($L$173:$L$252,MATCH(ROW()-25,$N$173:$N$252,0))) -> 0.57027027 | M34: =IF($A34="","",IF($K$106=0,"",$K34/$K$106)) -> 0.071264943
A35: =IFERROR(INDEX($A$173:$A$252,MATCH(ROW()-25,$N$173:$N$252,0)),"") -> Q25008-0100D | B35: =IF($A35="","",INDEX($B$173:$B$252,MATCH(ROW()-25,$N$173:$N$252,0))) -> 5 | C35: =IF($A35="","",INDEX($C$173:$C$252,MATCH(ROW()-25,$N$173:$N$252,0))) -> 46023 | D35: =IF($A35="","",INDEX($D$173:$D$252,MATCH(ROW()-25,$N$173:$N$252,0))) -> 46235 | E35: =IF($A35="","",INDEX($E$173:$E$252,MATCH(ROW()-25,$N$173:$N$252,0))) -> Finalized | F35: =IF($A35="","",INDEX($F$173:$F$252,MATCH(ROW()-25,$N$173:$N$252,0))) -> 1 | G35: =IF($A35="","",INDEX($G$173:$G$252,MATCH(ROW()-25,$N$173:$N$252,0))) -> 1.9297297 | H35: =IF($A35="","",INDEX($H$173:$H$252,MATCH(ROW()-25,$N$173:$N$252,0))) -> 1.9297297 | I35: =IF($A35="","",INDEX($I$173:$I$252,MATCH(ROW()-25,$N$173:$N$252,0))) -> 0 | J35: =IF($A35="","",INDEX($J$173:$J$252,MATCH(ROW()-25,$N$173:$N$252,0))) -> 3.0702703 | K35: =IF($A35="","",INDEX($K$173:$K$252,MATCH(ROW()-25,$N$173:$N$252,0))) -> 5 | L35: =IF($A35="","",INDEX($L$173:$L$252,MATCH(ROW()-25,$N$173:$N$252,0))) -> 1.8135135 | M35: =IF($A35="","",IF($K$106=0,"",$K35/$K$106)) -> 0.11153452
A36: =IFERROR(INDEX($A$173:$A$252,MATCH(ROW()-25,$N$173:$N$252,0)),"") -> AN24185-0100R | B36: =IF($A36="","",INDEX($B$173:$B$252,MATCH(ROW()-25,$N$173:$N$252,0))) -> 4 | C36: =IF($A36="","",INDEX($C$173:$C$252,MATCH(ROW()-25,$N$173:$N$252,0))) -> 45566 | D36: =IF($A36="","",INDEX($D$173:$D$252,MATCH(ROW()-25,$N$173:$N$252,0))) -> 46112 | E36: =IF($A36="","",INDEX($E$173:$E$252,MATCH(ROW()-25,$N$173:$N$252,0))) -> Finalized | F36: =IF($A36="","",INDEX($F$173:$F$252,MATCH(ROW()-25,$N$173:$N$252,0))) -> 1 | G36: =IF($A36="","",INDEX($G$173:$G$252,MATCH(ROW()-25,$N$173:$N$252,0))) -> 2.9608108 | H36: =IF($A36="","",INDEX($H$173:$H$252,MATCH(ROW()-25,$N$173:$N$252,0))) -> 2.9608108 | I36: =IF($A36="","",INDEX($I$173:$I$252,MATCH(ROW()-25,$N$173:$N$252,0))) -> 0 | J36: =IF($A36="","",INDEX($J$173:$J$252,MATCH(ROW()-25,$N$173:$N$252,0))) -> 1.0391892 | K36: =IF($A36="","",INDEX($K$173:$K$252,MATCH(ROW()-25,$N$173:$N$252,0))) -> 0.65813528 | L36: =IF($A36="","",INDEX($L$173:$L$252,MATCH(ROW()-25,$N$173:$N$252,0))) -> 0.13378378 | M36: =IF($A36="","",IF($K$106=0,"",$K36/$K$106)) -> 0.01468096
A37: =IFERROR(INDEX($A$173:$A$252,MATCH(ROW()-25,$N$173:$N$252,0)),"") -> AN24135-0100R | B37: =IF($A37="","",INDEX($B$173:$B$252,MATCH(ROW()-25,$N$173:$N$252,0))) -> 4 | C37: =IF($A37="","",INDEX($C$173:$C$252,MATCH(ROW()-25,$N$173:$N$252,0))) -> 45566 | D37: =IF($A37="","",INDEX($D$173:$D$252,MATCH(ROW()-25,$N$173:$N$252,0))) -> 46477 | E37: =IF($A37="","",INDEX($E$173:$E$252,MATCH(ROW()-25,$N$173:$N$252,0))) -> On Hold | F37: =IF($A37="","",INDEX($F$173:$F$252,MATCH(ROW()-25,$N$173:$N$252,0))) -> 0.1 | G37: =IF($A37="","",INDEX($G$173:$G$252,MATCH(ROW()-25,$N$173:$N$252,0))) -> 1.8310811 | H37: =IF($A37="","",INDEX($H$173:$H$252,MATCH(ROW()-25,$N$173:$N$252,0))) -> 18.310811 | I37: =IF($A37="","",INDEX($I$173:$I$252,MATCH(ROW()-25,$N$173:$N$252,0))) -> 16.47973 | J37: =IF($A37="","",INDEX($J$173:$J$252,MATCH(ROW()-25,$N$173:$N$252,0))) -> -14.310811 | K37: =IF($A37="","",INDEX($K$173:$K$252,MATCH(ROW()-25,$N$173:$N$252,0))) -> 1.6008772 | L37: =IF($A37="","",INDEX($L$173:$L$252,MATCH(ROW()-25,$N$173:$N$252,0))) -> 0 | M37: =IF($A37="","",IF($K$106=0,"",$K37/$K$106)) -> 0.035710613
... A105: =IFERROR(INDEX($A$173:$A$252,MATCH(ROW()-25,$N$173:$N$252,0)),"") | B105: =IF($A105="","",INDEX($B$173:$B$252,MATCH(ROW()-25,$N$173:$N$252,0))) | C105: =IF($A105="","",INDEX($C$173:$C$252,MATCH(ROW()-25,$N$173:$N$252,0))) | D105: =IF($A105="","",INDEX($D$173:$D$252,MATCH(ROW()-25,$N$173:$N$252,0))) | E105: =IF($A105="","",INDEX($E$173:$E$252,MATCH(ROW()-25,$N$173:$N$252,0))) | F105: =IF($A105="","",INDEX($F$173:$F$252,MATCH(ROW()-25,$N$173:$N$252,0))) | G105: =IF($A105="","",INDEX($G$173:$G$252,MATCH(ROW()-25,$N$173:$N$252,0))) | H105: =IF($A105="","",INDEX($H$173:$H$252,MATCH(ROW()-25,$N$173:$N$252,0))) | I105: =IF($A105="","",INDEX($I$173:$I$252,MATCH(ROW()-25,$N$173:$N$252,0))) | J105: =IF($A105="","",INDEX($J$173:$J$252,MATCH(ROW()-25,$N$173:$N$252,0))) | K105: =IF($A105="","",INDEX($K$173:$K$252,MATCH(ROW()-25,$N$173:$N$252,0))) | L105: =IF($A105="","",INDEX($L$173:$L$252,MATCH(ROW()-25,$N$173:$N$252,0))) | M105: =IF($A105="","",IF($K$106=0,"",$K105/$K$106))
A106: ="TOTAL — "&COUNTIF($A$26:$A$105,"?*")&" project(s) live in period" -> TOTAL — 16 project(s) live in period | B106: =SUM(B26:B105) -> 67.95 | F106: {=IF(B106=0,"",SUMPRODUCT($B$26:$B$105,IF($F$26:$F$105="",0,$F$26:$F$105))/B106)} -> 0.46668138 | G106: =SUM(G26:G105) -> 33.558108 | H106: =SUM(H26:H105) -> 113.89859 | I106: =SUM(I26:I105) -> 80.34048 | J106: =SUM(J26:J105) -> -45.948588 | K106: =SUM(K26:K105) -> 44.829171 | L106: =SUM(L26:L105) -> 17.467568 | M106: =IF($K$106=0,"",1) -> 1
A108: RESOURCE DETAIL — BY ENGINEER (selected period)
A109: Metric | B109: =Inputs!$A$91 -> Ahmed | C109: =Inputs!$A$92 -> Osama | D109: =Inputs!$A$93 -> Kirolos | E109: Total
A110: Actual MM booked in period | B110: =IF($B$5="All Time",Phasing!$Y$680,IF($B$5="Year",SUMIF(Phasing!$E$3:$X$3,$D$5,Phasing!$E$680:$X$680),SUMIF(Phasing!$E$4:$X$4,$B$6,Phasing!$E$680:$X$680))) -> 5.7216216 | C110: =IF($B$5="All Time",Phasing!$Y$681,IF($B$5="Year",SUMIF(Phasing!$E$3:$X$3,$D$5,Phasing!$E$681:$X$681),SUMIF(Phasing!$E$4:$X$4,$B$6,Phasing!$E$681:$X$681))) -> 5.9945946 | D110: =IF($B$5="All Time",Phasing!$Y$682,IF($B$5="Year",SUMIF(Phasing!$E$3:$X$3,$D$5,Phasing!$E$682:$X$682),SUMIF(Phasing!$E$4:$X$4,$B$6,Phasing!$E$682:$X$682))) -> 6.1918919 | E110: =SUM(B110:D110) -> 17.908108
A111: Share of team time in period | B111: =IF($E$110=0,"",B110/$E$110) -> 0.31949894 | C111: =IF($E$110=0,"",C110/$E$110) -> 0.33474193 | D111: =IF($E$110=0,"",D110/$E$110) -> 0.34575913 | E111: =IF(E110=0,"",SUM(B111:D111)) -> 1
A112: Remaining on hand allocated (MM) | B112: =SUMPRODUCT($I$173:$I$252,Inputs!$M$6:$M$85,$M$173:$M$252,Inputs!$I$6:$I$85) -> 22.961746 | C112: =SUMPRODUCT($I$173:$I$252,Inputs!$M$6:$M$85,$M$173:$M$252,Inputs!$J$6:$J$85) -> 24.440535 | D112: =SUMPRODUCT($I$173:$I$252,Inputs!$M$6:$M$85,$M$173:$M$252,Inputs!$K$6:$K$85) -> 6.1658979 | E112: =SUM(B112:D112) -> 53.568178
...

Sheet Mgmt Review
A1: MANAGEMENT REVIEW — TEAM PERFORMANCE
A2: ="Viewing: "&Dashboard!$H$5&" | All effort in Man-Months (MM) | Reported "&TEXT(TODAY(),"dd mmm yyyy") -> Viewing: Full year 2026 | All effort in Man-Months (MM) | Reported 01 Sep 2026
A4: To change the period, use the View by / Year / Quarter selectors at the top of the Dashboard sheet — this sheet follows them automatically.
A5: ="As at "&TEXT(Dashboard!$H$6,"dd mmm yyyy")&" — "&TEXT(Dashboard!$J$6,"0.0%")&" of the selected period has elapsed. Capacity and plan adherence are pro-rated accordingly, so a part-finished year is not compared against a full year of capacity." -> As at 01 Sep 2026 — 67.1% of the selected period has elapsed. Capacity and plan adherence are pro-rated accordingly, so a part-finished year is not compared against a full year of capacity.
A6: PERFORMANCE IN THE SELECTED PERIOD
A7: Team totals | B7: Planned MM (full period) | C7: Actual MM | D7: Earned MM | E7: Profit / (Loss) | F7: Capacity to Date | G7: Utilisation | H7: Plan Adherence to Date | I7: Efficiency (CPI) | J7: Projects Active
B8: =Dashboard!$B$10 -> 44.829171 | C8: =Dashboard!$C$10 -> 17.908108 | D8: =Dashboard!$D$10 -> 14.186137 | E8: =Dashboard!$E$10 -> -3.7219708 | F8: =Dashboard!$F$10 -> 24.163043 | G8: =Dashboard!$G$10 -> 0.74113628 | H8: =Dashboard!$H$10 -> 0.54727687 | I8: =Dashboard!$I$10 -> 0.79216281 | J8: =Dashboard!$J$10 -> 16
B9: ="what we said we would burn" -> what we said we would burn | C9: ="what we actually burned" -> what we actually burned | D9: ="value delivered" -> value delivered | E9: ="earned minus actual" -> earned minus actual | F9: ="pro-rated to "&TEXT(Dashboard!$H$6,"dd mmm") -> pro-rated to 01 Sep | G9: ="actual vs capacity" -> actual vs capacity | H9: ="vs "&TEXT(Dashboard!$L$6,"0.00")&" MM planned to date" -> vs 32.72 MM planned to date | I9: ="above 1.00 is good" -> above 1.00 is good | J9: ="live in this period" -> live in this period
A11: TEAM KPIs BY ENGINEER — SELECTED PERIOD
A12: KPI | B12: =Inputs!$A$91 -> Ahmed | C12: =Inputs!$A$92 -> Osama | D12: =Inputs!$A$93 -> Kirolos | E12: Team Total
A13: Actual MM booked | B13: =IF(Dashboard!$B$5="All Time",Phasing!$Y$680,IF(Dashboard!$B$5="Year",SUMIF(Phasing!$E$3:$X$3,Dashboard!$D$5,Phasing!$E$680:$X$680),SUMIF(Phasing!$E$4:$X$4,Dashboard!$B$6,Phasing!$E$680:$X$680))) -> 5.7216216 | C13: =IF(Dashboard!$B$5="All Time",Phasing!$Y$681,IF(Dashboard!$B$5="Year",SUMIF(Phasing!$E$3:$X$3,Dashboard!$D$5,Phasing!$E$681:$X$681),SUMIF(Phasing!$E$4:$X$4,Dashboard!$B$6,Phasing!$E$681:$X$681))) -> 5.9945946 | D13: =IF(Dashboard!$B$5="All Time",Phasing!$Y$682,IF(Dashboard!$B$5="Year",SUMIF(Phasing!$E$3:$X$3,Dashboard!$D$5,Phasing!$E$682:$X$682),SUMIF(Phasing!$E$4:$X$4,Dashboard!$B$6,Phasing!$E$682:$X$682))) -> 6.1918919 | E13: =SUM(B13:D13) -> 17.908108
A14: Planned MM to date (by allocation) | B14: =SUMPRODUCT(Dashboard!$P$173:$P$252,Inputs!$I$6:$I$85) -> 12.228239 | C14: =SUMPRODUCT(Dashboard!$P$173:$P$252,Inputs!$J$6:$J$85) -> 9.3573832 | D14: =SUMPRODUCT(Dashboard!$P$173:$P$252,Inputs!$K$6:$K$85) -> 11.136587 | E14: =SUM(B14:D14) -> 32.722209
A15: Earned MM (by allocation) | B15: =SUMPRODUCT(Dashboard!$O$173:$O$252,Inputs!$I$6:$I$85) -> 5.1198091 | C15: =SUMPRODUCT(Dashboard!$O$173:$O$252,Inputs!$J$6:$J$85) -> 3.781334 | D15: =SUMPRODUCT(Dashboard!$O$173:$O$252,Inputs!$K$6:$K$85) -> 5.2849942 | E15: =SUM(B15:D15) -> 14.186137
A16: Profit / (Loss) contribution | B16: =B15-B13 -> -0.60181251 | C16: =C15-C13 -> -2.2132606 | D16: =D15-D13 -> -0.9068977 | E16: =E15-E13 -> -3.7219708
A17: Capacity MM to date | B17: =(IF(Dashboard!$B$5="All Time",SUM(Inputs!$B$91:$F$91)*4*Inputs!$B$94,IF(Dashboard!$B$5="Year",SUMIF(Inputs!$B$90:$F$90,Dashboard!$D$5,Inputs!$B$91:$F$91)*4*Inputs!$B$94,SUMIF(Inputs!$B$90:$F$90,Dashboard!$D$5,Inputs!$B$91:$F$91)*Inputs!$B$94)))*IF(Dashboard!$J$6="",0,Dashboard!$J$6) -> 8.0543478 | C17: =(IF(Dashboard!$B$5="All Time",SUM(Inputs!$B$92:$F$92)*4*Inputs!$B$94,IF(Dashboard!$B$5="Year",SUMIF(Inputs!$B$90:$F$90,Dashboard!$D$5,Inputs!$B$92:$F$92)*4*Inputs!$B$94,SUMIF(Inputs!$B$90:$F$90,Dashboard!$D$5,Inputs!$B$92:$F$92)*Inputs!$B$94)))*IF(Dashboard!$J$6="",0,Dashboard!$J$6) -> 8.0543478 | D17: =(IF(Dashboard!$B$5="All Time",SUM(Inputs!$B$93:$F$93)*4*Inputs!$B$94,IF(Dashboard!$B$5="Year",SUMIF(Inputs!$B$90:$F$90,Dashboard!$D$5,Inputs!$B$93:$F$93)*4*Inputs!$B$94,SUMIF(Inputs!$B$90:$F$90,Dashboard!$D$5,Inputs!$B$93:$F$93)*Inputs!$B$94)))*IF(Dashboard!$J$6="",0,Dashboard!$J$6) -> 8.0543478 | E17: =SUM(B17:D17) -> 24.163043
A18: Utilisation vs capacity to date | B18: =IF(B17=0,"n/a",B13/B17) -> 0.71037677 | C18: =IF(C17=0,"n/a",C13/C17) -> 0.74426815 | D18: =IF(D17=0,"n/a",D13/D17) -> 0.76876391 | E18: =IF(E17=0,"n/a",E13/E17) -> 0.74113628
A19: Plan adherence to date | B19: =IF(B14=0,"n/a",B13/B14) -> 0.46790235 | C19: =IF(C14=0,"n/a",C13/C14) -> 0.64062724 | D19: =IF(D14=0,"n/a",D13/D14) -> 0.55599547 | E19: =IF(E14=0,"n/a",E13/E14) -> 0.54727687
A20: Efficiency (CPI) | B20: =IF(B13=0,"n/a",B15/B13) -> 0.89481784 | C20: =IF(C13=0,"n/a",C15/C13) -> 0.63079062 | D20: =IF(D13=0,"n/a",D15/D13) -> 0.85353464 | E20: =IF(E13=0,"n/a",E15/E13) -> 0.79216281
A21: Share of team time booked | B21: =IF($E$13=0,"",B13/$E$13) -> 0.31949894 | C21: =IF($E$13=0,"",C13/$E$13) -> 0.33474193 | D21: =IF($E$13=0,"",D13/$E$13) -> 0.34575913 | E21: =IF(E13=0,"",SUM(B21:D21)) -> 1
A22: Remaining on hand allocated | B22: =SUMPRODUCT(Dashboard!$I$173:$I$252,Inputs!$M$6:$M$85,Dashboard!$M$173:$M$252,Inputs!$I$6:$I$85) -> 22.961746 | C22: =SUMPRODUCT(Dashboard!$I$173:$I$252,Inputs!$M$6:$M$85,Dashboard!$M$173:$M$252,Inputs!$J$6:$J$85) -> 24.440535 | D22: =SUMPRODUCT(Dashboard!$I$173:$I$252,Inputs!$M$6:$M$85,Dashboard!$M$173:$M$252,Inputs!$K$6:$K$85) -> 6.1658979 | E22: =SUM(B22:D22) -> 53.568178
A24: TYPE-WEIGHTED VIEW — PERSONAL SCORING ONLY (never applied to project financials)
A25: Type-weighted Earned MM (KPI only) | B25: =SUMPRODUCT(Dashboard!$O$173:$O$252,Inputs!$V$6:$V$85,Inputs!$I$6:$I$85) -> 4.7902585 | C25: =SUMPRODUCT(Dashboard!$O$173:$O$252,Inputs!$V$6:$V$85,Inputs!$J$6:$J$85) -> 3.8375137 | D25: =SUMPRODUCT(Dashboard!$O$173:$O$252,Inputs!$V$6:$V$85,Inputs!$K$6:$K$85) -> 4.531845 | E25: =SUM(B25:D25) -> 13.159617
A26: Type-weighted Efficiency (CPI, KPI only) | B26: =IF(B13=0,"n/a",B25/B13) -> 0.83722042 | C26: =IF(C13=0,"n/a",C25/C13) -> 0.64016234 | D26: =IF(D13=0,"n/a",D25/D13) -> 0.73189989 | E26: =IF(E13=0,"n/a",E25/E13) -> 0.73484129
A27: Average type factor of work delivered | B27: =IF(B15=0,"n/a",B25/B15) -> 0.93563224 | C27: =IF(C15=0,"n/a",C25/C15) -> 1.0148571 | D27: =IF(D15=0,"n/a",D25/D15) -> 0.8574929 | E27: =IF(E15=0,"n/a",E25/E15) -> 0.92763921
A30: TEAM PERFORMANCE DEPENDENCY - DRAFTSMEN AND BENGALURU
A31: Cairo hours come from the timesheet. Bengaluru and draftsman hours are entered per deliverable on the Support Plan sheet. Until those are filled in, delivery reads as 100% Cairo.
A33: DELIVERY MIX | B33: Hours | C33: Share | D33: Man-months
A34: Cairo team (from timesheet) | B34: =SUM('Support Plan'!$K$5:$K$68) -> 11970 | C34: =IF($B$37=0,"",$B34/$B$37) -> 1 | D34: =$B34/'Profit Plan'!$B$5 -> 64.702703
A35: Bengaluru support | B35: =SUM('Support Plan'!$I$5:$I$68) -> 0 | C35: =IF($B$37=0,"",$B35/$B$37) -> 0 | D35: =$B35/'Profit Plan'!$B$5 -> 0
A36: Draftsman support | B36: =SUM('Support Plan'!$J$5:$J$68) -> 0 | C36: =IF($B$37=0,"",$B36/$B$37) -> 0 | D36: =$B36/'Profit Plan'!$B$5 -> 0
A37: Total delivered | B37: =SUM($B$34:$B$36) -> 11970 | C37: =IF($B$37=0,"",1) -> 1 | D37: =$B37/'Profit Plan'!$B$5 -> 64.702703
A39: BENGALURU: PLAN VERSUS REALITY
A40: Planned Bengaluru hours | B40: ='Support Plan'!$T$7 -> 0
A41: Actual Bengaluru hours | B41: ='Support Plan'!$T$8 -> 0
A42: Shortfall absorbed by Cairo (hours) | B42: ='Support Plan'!$T$9 -> 0
A43: Shortfall absorbed by Cairo (man-months) | B43: ='Support Plan'!$T$10 -> 0
A44: As a share of Cairo capacity left this year | B44: =IF('Profit Plan'!$B$11=0,"",$B$43/'Profit Plan'!$B$11) -> 0
A45: Deliverables shifted away from the planned office | B45: ='Support Plan'!$T$6 -> 0
A47: DRAFTSMAN DEPENDENCY
A48: Planned draftsman hours | B48: ='Support Plan'!$T$11 -> 0
...

Sheet Engineer KPIs
A1: ENGINEER KPIs — SELECTED PERIOD
A2: ="Viewing: "&Dashboard!$H$5&" | All effort in Man-Months (MM) | Reported "&TEXT(TODAY(),"dd mmm yyyy") -> Viewing: Full year 2026 | All effort in Man-Months (MM) | Reported 01 Sep 2026
A4: Period is controlled from the Dashboard sheet. This sheet and the Management Review sheet both follow it.
A5: ="As at "&TEXT(Dashboard!$H$6,"dd mmm yyyy")&" — "&TEXT(Dashboard!$J$6,"0.0%")&" of the selected period has elapsed. Capacity and plan adherence are pro-rated accordingly." -> As at 01 Sep 2026 — 67.1% of the selected period has elapsed. Capacity and plan adherence are pro-rated accordingly.
A6: KPI SUMMARY BY ENGINEER
A7: KPI | B7: =Inputs!$A$91 -> Ahmed | C7: =Inputs!$A$92 -> Osama | D7: =Inputs!$A$93 -> Kirolos | E7: Team Total
A8: Actual MM booked | B8: ='Mgmt Review'!B13 -> 5.7216216 | C8: ='Mgmt Review'!C13 -> 5.9945946 | D8: ='Mgmt Review'!D13 -> 6.1918919 | E8: ='Mgmt Review'!E13 -> 17.908108
A9: Planned MM to date (by allocation) | B9: ='Mgmt Review'!B14 -> 12.228239 | C9: ='Mgmt Review'!C14 -> 9.3573832 | D9: ='Mgmt Review'!D14 -> 11.136587 | E9: ='Mgmt Review'!E14 -> 32.722209
A10: Earned MM (by allocation) | B10: ='Mgmt Review'!B15 -> 5.1198091 | C10: ='Mgmt Review'!C15 -> 3.781334 | D10: ='Mgmt Review'!D15 -> 5.2849942 | E10: ='Mgmt Review'!E15 -> 14.186137
A11: Profit / (Loss) contribution | B11: ='Mgmt Review'!B16 -> -0.60181251 | C11: ='Mgmt Review'!C16 -> -2.2132606 | D11: ='Mgmt Review'!D16 -> -0.9068977 | E11: ='Mgmt Review'!E16 -> -3.7219708
A12: Capacity MM to date | B12: ='Mgmt Review'!B17 -> 8.0543478 | C12: ='Mgmt Review'!C17 -> 8.0543478 | D12: ='Mgmt Review'!D17 -> 8.0543478 | E12: ='Mgmt Review'!E17 -> 24.163043
A13: Utilisation vs capacity to date | B13: ='Mgmt Review'!B18 -> 0.71037677 | C13: ='Mgmt Review'!C18 -> 0.74426815 | D13: ='Mgmt Review'!D18 -> 0.76876391 | E13: ='Mgmt Review'!E18 -> 0.74113628
A14: Plan adherence to date | B14: ='Mgmt Review'!B19 -> 0.46790235 | C14: ='Mgmt Review'!C19 -> 0.64062724 | D14: ='Mgmt Review'!D19 -> 0.55599547 | E14: ='Mgmt Review'!E19 -> 0.54727687
A15: Efficiency (CPI) | B15: ='Mgmt Review'!B20 -> 0.89481784 | C15: ='Mgmt Review'!C20 -> 0.63079062 | D15: ='Mgmt Review'!D20 -> 0.85353464 | E15: ='Mgmt Review'!E20 -> 0.79216281
A16: Share of team time booked | B16: ='Mgmt Review'!B21 -> 0.31949894 | C16: ='Mgmt Review'!C21 -> 0.33474193 | D16: ='Mgmt Review'!D21 -> 0.34575913 | E16: ='Mgmt Review'!E21 -> 1
A17: Remaining on hand allocated | B17: ='Mgmt Review'!B22 -> 22.961746 | C17: ='Mgmt Review'!C22 -> 24.440535 | D17: ='Mgmt Review'!D22 -> 6.1658979 | E17: ='Mgmt Review'!E22 -> 53.568178
A18: Projects worked in period | B18: =COUNTIF($C$181:$C$260,">0") -> 6 | C18: =COUNTIF($D$181:$D$260,">0") -> 4 | D18: =COUNTIF($E$181:$E$260,">0") -> 7 | E18: =COUNTIF($F$181:$F$260,">0") -> 11
A19: Average MM per project worked | B19: =IF(B18=0,"n/a",B8/B18) -> 0.9536036 | C19: =IF(C18=0,"n/a",C8/C18) -> 1.4986486 | D19: =IF(D18=0,"n/a",D8/D18) -> 0.88455598 | E19: =IF(E18=0,"n/a",E8/E18) -> 1.6280098
A20: Months of work outstanding | B20: =IF(SUMIF(Inputs!$B$90:$F$90,Dashboard!$D$5,Inputs!$B$91:$F$91)*4*Inputs!$B$94=0,"n/a",B17/(SUMIF(Inputs!$B$90:$F$90,Dashboard!$D$5,Inputs!$B$91:$F$91)*4*Inputs!$B$94)*12) -> 22.961746 | C20: =IF(SUMIF(Inputs!$B$90:$F$90,Dashboard!$D$5,Inputs!$B$92:$F$92)*4*Inputs!$B$94=0,"n/a",C17/(SUMIF(Inputs!$B$90:$F$90,Dashboard!$D$5,Inputs!$B$92:$F$92)*4*Inputs!$B$94)*12) -> 24.440535 | D20: =IF(SUMIF(Inputs!$B$90:$F$90,Dashboard!$D$5,Inputs!$B$93:$F$93)*4*Inputs!$B$94=0,"n/a",D17/(SUMIF(Inputs!$B$90:$F$90,Dashboard!$D$5,Inputs!$B$93:$F$93)*4*Inputs!$B$94)*12) -> 6.1658979 | E20: =IF(SUM(Inputs!$B$91:$B$93)=0,"n/a",E17/(SUMIF(Inputs!$B$90:$F$90,Dashboard!$D$5,Inputs!$B$91:$F$91)*4*Inputs!$B$94+SUMIF(Inputs!$B$90:$F$90,Dashboard!$D$5,Inputs!$B$92:$F$92)*4*Inputs!$B$94+SUMIF(Inputs!$B$90:$F$90,Dashboard!$D$5,Inputs!$B$93:$F$93)*4*Inputs!$B$94)*12) -> 17.856059
A22: WHO WORKED ON WHAT — ACTUAL MM IN THE SELECTED PERIOD
A23: Project | B23: Status | C23: =Inputs!$A$91 -> Ahmed | D23: =Inputs!$A$92 -> Osama | E23: =Inputs!$A$93 -> Kirolos | F23: Total
A24: =IFERROR(INDEX($A$181:$A$260,MATCH(ROW()-23,$G$181:$G$260,0)),"") -> E26084-0100D | B24: =IF($A24="","",INDEX($B$181:$B$260,MATCH(ROW()-23,$G$181:$G$260,0))) -> Active | C24: =IF($A24="","",INDEX($C$181:$C$260,MATCH(ROW()-23,$G$181:$G$260,0))) -> 0 | D24: =IF($A24="","",INDEX($D$181:$D$260,MATCH(ROW()-23,$G$181:$G$260,0))) -> 0.22567568 | E24: =IF($A24="","",INDEX($E$181:$E$260,MATCH(ROW()-23,$G$181:$G$260,0))) -> 0 | F24: =IF($A24="","",INDEX($F$181:$F$260,MATCH(ROW()-23,$G$181:$G$260,0))) -> 0.22567568
A25: =IFERROR(INDEX($A$181:$A$260,MATCH(ROW()-23,$G$181:$G$260,0)),"") -> N25185-0100D | B25: =IF($A25="","",INDEX($B$181:$B$260,MATCH(ROW()-23,$G$181:$G$260,0))) -> Active | C25: =IF($A25="","",INDEX($C$181:$C$260,MATCH(ROW()-23,$G$181:$G$260,0))) -> 5.1 | D25: =IF($A25="","",INDEX($D$181:$D$260,MATCH(ROW()-23,$G$181:$G$260,0))) -> 5.4189189 | E25: =IF($A25="","",INDEX($E$181:$E$260,MATCH(ROW()-23,$G$181:$G$260,0))) -> 2.9986486 | F25: =IF($A25="","",INDEX($F$181:$F$260,MATCH(ROW()-23,$G$181:$G$260,0))) -> 13.517568
A26: =IFERROR(INDEX($A$181:$A$260,MATCH(ROW()-23,$G$181:$G$260,0)),"") -> AN24140-0100R | B26: =IF($A26="","",INDEX($B$181:$B$260,MATCH(ROW()-23,$G$181:$G$260,0))) -> Active | C26: =IF($A26="","",INDEX($C$181:$C$260,MATCH(ROW()-23,$G$181:$G$260,0))) -> 0 | D26: =IF($A26="","",INDEX($D$181:$D$260,MATCH(ROW()-23,$G$181:$G$260,0))) -> 0 | E26: =IF($A26="","",INDEX($E$181:$E$260,MATCH(ROW()-23,$G$181:$G$260,0))) -> 0.021621622 | F26: =IF($A26="","",INDEX($F$181:$F$260,MATCH(ROW()-23,$G$181:$G$260,0))) -> 0.021621622
A27: =IFERROR(INDEX($A$181:$A$260,MATCH(ROW()-23,$G$181:$G$260,0)),"") -> CS24035-0100D | B27: =IF($A27="","",INDEX($B$181:$B$260,MATCH(ROW()-23,$G$181:$G$260,0))) -> On Hold | C27: =IF($A27="","",INDEX($C$181:$C$260,MATCH(ROW()-23,$G$181:$G$260,0))) -> 0.10675676 | D27: =IF($A27="","",INDEX($D$181:$D$260,MATCH(ROW()-23,$G$181:$G$260,0))) -> 0 | E27: =IF($A27="","",INDEX($E$181:$E$260,MATCH(ROW()-23,$G$181:$G$260,0))) -> 0.46351351 | F27: =IF($A27="","",INDEX($F$181:$F$260,MATCH(ROW()-23,$G$181:$G$260,0))) -> 0.57027027
A28: =IFERROR(INDEX($A$181:$A$260,MATCH(ROW()-23,$G$181:$G$260,0)),"") -> Q25008-0100D | B28: =IF($A28="","",INDEX($B$181:$B$260,MATCH(ROW()-23,$G$181:$G$260,0))) -> Finalized | C28: =IF($A28="","",INDEX($C$181:$C$260,MATCH(ROW()-23,$G$181:$G$260,0))) -> 0.14594595 | D28: =IF($A28="","",INDEX($D$181:$D$260,MATCH(ROW()-23,$G$181:$G$260,0))) -> 0 | E28: =IF($A28="","",INDEX($E$181:$E$260,MATCH(ROW()-23,$G$181:$G$260,0))) -> 1.6675676 | F28: =IF($A28="","",INDEX($F$181:$F$260,MATCH(ROW()-23,$G$181:$G$260,0))) -> 1.8135135
A29: =IFERROR(INDEX($A$181:$A$260,MATCH(ROW()-23,$G$181:$G$260,0)),"") -> AN24185-0100R | B29: =IF($A29="","",INDEX($B$181:$B$260,MATCH(ROW()-23,$G$181:$G$260,0))) -> Finalized | C29: =IF($A29="","",INDEX($C$181:$C$260,MATCH(ROW()-23,$G$181:$G$260,0))) -> 0 | D29: =IF($A29="","",INDEX($D$181:$D$260,MATCH(ROW()-23,$G$181:$G$260,0))) -> 0 | E29: =IF($A29="","",INDEX($E$181:$E$260,MATCH(ROW()-23,$G$181:$G$260,0))) -> 0.13378378 | F29: =IF($A29="","",INDEX($F$181:$F$260,MATCH(ROW()-23,$G$181:$G$260,0))) -> 0.13378378
A30: =IFERROR(INDEX($A$181:$A$260,MATCH(ROW()-23,$G$181:$G$260,0)),"") -> AN23108-0100R | B30: =IF($A30="","",INDEX($B$181:$B$260,MATCH(ROW()-23,$G$181:$G$260,0))) -> On Hold | C30: =IF($A30="","",INDEX($C$181:$C$260,MATCH(ROW()-23,$G$181:$G$260,0))) -> 0 | D30: =IF($A30="","",INDEX($D$181:$D$260,MATCH(ROW()-23,$G$181:$G$260,0))) -> 0 | E30: =IF($A30="","",INDEX($E$181:$E$260,MATCH(ROW()-23,$G$181:$G$260,0))) -> 0.68513514 | F30: =IF($A30="","",INDEX($F$181:$F$260,MATCH(ROW()-23,$G$181:$G$260,0))) -> 0.68513514
A31: =IFERROR(INDEX($A$181:$A$260,MATCH(ROW()-23,$G$181:$G$260,0)),"") -> TA24246-0200R | B31: =IF($A31="","",INDEX($B$181:$B$260,MATCH(ROW()-23,$G$181:$G$260,0))) -> On Hold | C31: =IF($A31="","",INDEX($C$181:$C$260,MATCH(ROW()-23,$G$181:$G$260,0))) -> 0 | D31: =IF($A31="","",INDEX($D$181:$D$260,MATCH(ROW()-23,$G$181:$G$260,0))) -> 0.098648649 | E31: =IF($A31="","",INDEX($E$181:$E$260,MATCH(ROW()-23,$G$181:$G$260,0))) -> 0 | F31: =IF($A31="","",INDEX($F$181:$F$260,MATCH(ROW()-23,$G$181:$G$260,0))) -> 0.098648649
A32: =IFERROR(INDEX($A$181:$A$260,MATCH(ROW()-23,$G$181:$G$260,0)),"") -> N23106-0100D | B32: =IF($A32="","",INDEX($B$181:$B$260,MATCH(ROW()-23,$G$181:$G$260,0))) -> Finalized | C32: =IF($A32="","",INDEX($C$181:$C$260,MATCH(ROW()-23,$G$181:$G$260,0))) -> 0.18918919 | D32: =IF($A32="","",INDEX($D$181:$D$260,MATCH(ROW()-23,$G$181:$G$260,0))) -> 0.25135135 | E32: =IF($A32="","",INDEX($E$181:$E$260,MATCH(ROW()-23,$G$181:$G$260,0))) -> 0 | F32: =IF($A32="","",INDEX($F$181:$F$260,MATCH(ROW()-23,$G$181:$G$260,0))) -> 0.44054054
A33: =IFERROR(INDEX($A$181:$A$260,MATCH(ROW()-23,$G$181:$G$260,0)),"") -> Chargable Proposals 26 | B33: =IF($A33="","",INDEX($B$181:$B$260,MATCH(ROW()-23,$G$181:$G$260,0))) -> Active | C33: =IF($A33="","",INDEX($C$181:$C$260,MATCH(ROW()-23,$G$181:$G$260,0))) -> 0.10945946 | D33: =IF($A33="","",INDEX($D$181:$D$260,MATCH(ROW()-23,$G$181:$G$260,0))) -> 0 | E33: =IF($A33="","",INDEX($E$181:$E$260,MATCH(ROW()-23,$G$181:$G$260,0))) -> 0.22162162 | F33: =IF($A33="","",INDEX($F$181:$F$260,MATCH(ROW()-23,$G$181:$G$260,0))) -> 0.33108108
A34: =IFERROR(INDEX($A$181:$A$260,MATCH(ROW()-23,$G$181:$G$260,0)),"") -> Proposals 26 | B34: =IF($A34="","",INDEX($B$181:$B$260,MATCH(ROW()-23,$G$181:$G$260,0))) -> Active | C34: =IF($A34="","",INDEX($C$181:$C$260,MATCH(ROW()-23,$G$181:$G$260,0))) -> 0.07027027 | D34: =IF($A34="","",INDEX($D$181:$D$260,MATCH(ROW()-23,$G$181:$G$260,0))) -> 0 | E34: =IF($A34="","",INDEX($E$181:$E$260,MATCH(ROW()-23,$G$181:$G$260,0))) -> 0 | F34: =IF($A34="","",INDEX($F$181:$F$260,MATCH(ROW()-23,$G$181:$G$260,0))) -> 0.07027027
A35: =IFERROR(INDEX($A$181:$A$260,MATCH(ROW()-23,$G$181:$G$260,0)),"") | B35: =IF($A35="","",INDEX($B$181:$B$260,MATCH(ROW()-23,$G$181:$G$260,0))) | C35: =IF($A35="","",INDEX($C$181:$C$260,MATCH(ROW()-23,$G$181:$G$260,0))) | D35: =IF($A35="","",INDEX($D$181:$D$260,MATCH(ROW()-23,$G$181:$G$260,0))) | E35: =IF($A35="","",INDEX($E$181:$E$260,MATCH(ROW()-23,$G$181:$G$260,0))) | F35: =IF($A35="","",INDEX($F$181:$F$260,MATCH(ROW()-23,$G$181:$G$260,0)))
... A63: =IFERROR(INDEX($A$181:$A$260,MATCH(ROW()-23,$G$181:$G$260,0)),"") | B63: =IF($A63="","",INDEX($B$181:$B$260,MATCH(ROW()-23,$G$181:$G$260,0))) | C63: =IF($A63="","",INDEX($C$181:$C$260,MATCH(ROW()-23,$G$181:$G$260,0))) | D63: =IF($A63="","",INDEX($D$181:$D$260,MATCH(ROW()-23,$G$181:$G$260,0))) | E63: =IF($A63="","",INDEX($E$181:$E$260,MATCH(ROW()-23,$G$181:$G$260,0))) | F63: =IF($A63="","",INDEX($F$181:$F$260,MATCH(ROW()-23,$G$181:$G$260,0)))
A64: ="TOTAL — "&COUNTIF($A$24:$A$63,"?*")&" project(s) with time booked" -> TOTAL — 11 project(s) with time booked | C64: =SUM(C24:C63) -> 5.7216216 | D64: =SUM(D24:D63) -> 5.9945946 | E64: =SUM(E24:E63) -> 6.1918919 | F64: =SUM(F24:F63) -> 17.908108
A179: Helper — actual MM by project and engineer for the selected period. Do not edit.
A180: Code | B180: Status | C180: Ahmed | D180: Osama | E180: Kirolos | F180: Total | G180: Rank
A181: =IF(Inputs!$A6="","",Inputs!$A6) -> N25178-0100D | B181: =IF($A181="","",Inputs!$F6) -> Active | C181: =IF($A181="",0,IF(Dashboard!$B$5="All Time",Phasing!$Y265,IF(Dashboard!$B$5="Year",SUMIF(Phasing!$E$3:$X$3,Dashboard!$D$5,Phasing!$E265:$X265),SUMIF(Phasing!$E$4:$X$4,Dashboard!$B$6,Phasing!$E265:$X265)))) -> 0 | D181: =IF($A181="",0,IF(Dashboard!$B$5="All Time",Phasing!$Y266,IF(Dashboard!$B$5="Year",SUMIF(Phasing!$E$3:$X$3,Dashboard!$D$5,Phasing!$E266:$X266),SUMIF(Phasing!$E$4:$X$4,Dashboard!$B$6,Phasing!$E266:$X266)))) -> 0 | E181: =IF($A181="",0,IF(Dashboard!$B$5="All Time",Phasing!$Y267,IF(Dashboard!$B$5="Year",SUMIF(Phasing!$E$3:$X$3,Dashboard!$D$5,Phasing!$E267:$X267),SUMIF(Phasing!$E$4:$X$4,Dashboard!$B$6,Phasing!$E267:$X267)))) -> 0 | F181: =SUM($C181:$E181) -> 0 | G181: =IF($F181<=0,"",COUNTIF($F$181:$F181,">0"))
A182: =IF(Inputs!$A7="","",Inputs!$A7) -> E26084-0100D | B182: =IF($A182="","",Inputs!$F7) -> Active | C182: =IF($A182="",0,IF(Dashboard!$B$5="All Time",Phasing!$Y268,IF(Dashboard!$B$5="Year",SUMIF(Phasing!$E$3:$X$3,Dashboard!$D$5,Phasing!$E268:$X268),SUMIF(Phasing!$E$4:$X$4,Dashboard!$B$6,Phasing!$E268:$X268)))) -> 0 | D182: =IF($A182="",0,IF(Dashboard!$B$5="All Time",Phasing!$Y269,IF(Dashboard!$B$5="Year",SUMIF(Phasing!$E$3:$X$3,Dashboard!$D$5,Phasing!$E269:$X269),SUMIF(Phasing!$E$4:$X$4,Dashboard!$B$6,Phasing!$E269:$X269)))) -> 0.22567568 | E182: =IF($A182="",0,IF(Dashboard!$B$5="All Time",Phasing!$Y270,IF(Dashboard!$B$5="Year",SUMIF(Phasing!$E$3:$X$3,Dashboard!$D$5,Phasing!$E270:$X270),SUMIF(Phasing!$E$4:$X$4,Dashboard!$B$6,Phasing!$E270:$X270)))) -> 0 | F182: =SUM($C182:$E182) -> 0.22567568 | G182: =IF($F182<=0,"",COUNTIF($F$181:$F182,">0")) -> 1
A183: =IF(Inputs!$A8="","",Inputs!$A8) -> N25185-0100D | B183: =IF($A183="","",Inputs!$F8) -> Active | C183: =IF($A183="",0,IF(Dashboard!$B$5="All Time",Phasing!$Y271,IF(Dashboard!$B$5="Year",SUMIF(Phasing!$E$3:$X$3,Dashboard!$D$5,Phasing!$E271:$X271),SUMIF(Phasing!$E$4:$X$4,Dashboard!$B$6,Phasing!$E271:$X271)))) -> 5.1 | D183: =IF($A183="",0,IF(Dashboard!$B$5="All Time",Phasing!$Y272,IF(Dashboard!$B$5="Year",SUMIF(Phasing!$E$3:$X$3,Dashboard!$D$5,Phasing!$E272:$X272),SUMIF(Phasing!$E$4:$X$4,Dashboard!$B$6,Phasing!$E272:$X272)))) -> 5.4189189 | E183: =IF($A183="",0,IF(Dashboard!$B$5="All Time",Phasing!$Y273,IF(Dashboard!$B$5="Year",SUMIF(Phasing!$E$3:$X$3,Dashboard!$D$5,Phasing!$E273:$X273),SUMIF(Phasing!$E$4:$X$4,Dashboard!$B$6,Phasing!$E273:$X273)))) -> 2.9986486 | F183: =SUM($C183:$E183) -> 13.517568 | G183: =IF($F183<=0,"",COUNTIF($F$181:$F183,">0")) -> 2
...

Sheet Team Member
A1: ="PERSONAL PERFORMANCE REPORT — "&UPPER($B$4)&" | "&TEXT($D$4,"0") -> PERSONAL PERFORMANCE REPORT — AHMED | 2025
A2: All effort in Man-Months (MM). Choose your name and the year below — this sheet is independent of the Dashboard filter.
A4: Team member: | B4: Ahmed | C4: Year: | D4: 2025 | E4: As at: | F4: =Inputs!$B$96 -> 46266 | H4: =MATCH($B$4,Inputs!$A$91:$A$93,0) -> 1
A5: {="As at "&TEXT($F$4,"dd mmm yyyy")&", "&TEXT(SUMPRODUCT((Analysis!$E$3:$X$3=$D$4)*Analysis!$E$31:$X$31)/4,"0.0%")&" of "&TEXT($D$4,"0")&" has elapsed. Capacity and plan targets below are pro-rated to that point, not to 31 December."} -> As at 01 Sep 2026, 100.0% of 2025 has elapsed. Capacity and plan targets below are pro-rated to that point, not to 31 December. | H5: {=SUMPRODUCT((Analysis!$E$3:$X$3=$D$4)*Analysis!$E$31:$X$31)/4} -> 1
H6: {=IFERROR(INDEX(Inputs!$B$91:$F$93,$H$4,MATCH($D$4,Inputs!$B$90:$F$90,0))*4*Inputs!$B$94,0)} -> 12
A7: YOUR NUMBERS FOR THE YEAR
A8: Metric | B8: Value | C8: What it means
A9: Actual MM you booked | B9: =SUM($E$154:$E$233) -> 9.2594595 | C9: ="time you actually logged in "&TEXT($D$4,"0") -> time you actually logged in 2025
A10: Planned MM to date (your allocation) | B10: =SUMPRODUCT($H$154:$H$233,$F$154:$F$233) -> 22.761725 | C10: ="what the plan expected of you by "&TEXT($F$4,"dd mmm") -> what the plan expected of you by 01 Sep
A11: Earned MM (value you delivered) | B11: =SUMPRODUCT($D$154:$D$233,$F$154:$F$233) -> 20.015598 | C11: ="budget value earned on your share of the work" -> budget value earned on your share of the work
A12: Capacity MM to date | B12: =$H$6*$H$5 -> 12 | C12: ="your available time up to "&TEXT($F$4,"dd mmm") -> your available time up to 01 Sep
A13: Utilisation vs capacity to date | B13: =IF($B$12=0,"n/a",$B$9/$B$12) -> 0.77162162 | C13: =IF($B$13="n/a","no capacity set",IF($B$13>1,"above capacity — overloaded","within capacity")) -> within capacity
A14: Plan adherence to date | B14: =IF($B$10=0,"n/a",$B$9/$B$10) -> 0.40679955 | C14: =IF($B$14="n/a","no plan to compare",IF($B$14>1,"ahead of the plan","behind the plan")) -> behind the plan
A15: Efficiency (CPI) | B15: =IF($B$9=0,"n/a",$B$11/$B$9) -> 2.1616379 | C15: =IF($B$15="n/a","no time booked",IF($B$15>=1,"delivering more value than time spent","spending more time than value delivered")) -> delivering more value than time spent
A16: Projects you worked on | B16: =COUNTIF($E$154:$E$233,">0") -> 20 | C16: ="projects with time booked in the year" -> projects with time booked in the year
A17: Average MM per project | B17: =IF($B$16=0,"n/a",$B$9/$B$16) -> 0.46297297 | C17: ="average effort per project" -> average effort per project
